Workbook

Sheet r_names
A1: r_name | B1: ChemicalClass | C1: HMDB
A2: =AnalysisResults!A2 -> acetoacetic_acid | B2: Organic acids | C2: HMDB0000060
A3: =AnalysisResults!A3 -> adenosine | B3: Nucleoside | C3: HMDB0000050
A4: =AnalysisResults!A4 -> alanine | B4: Amino Acids | C4: HMDB0000161
A5: =AnalysisResults!A5 -> allantoin | B5: Azoles | C5: HMDB0000462
A6: =AnalysisResults!A6 -> alpha_aminoadipic_acid | B6: Amino acid - related | C6: HMDB0000510
A7: =AnalysisResults!A7 -> alpha_aminobutyric_acid | B7: Amino acid - related | C7: HMDB0000452
A8: =AnalysisResults!A8 -> alpha_ketoglutaric_acid | B8: Organic acids | C8: HMDB0000208
A9: =AnalysisResults!A9 -> alpha_ketoisovaleric_acid | B9: Organic acids | C9: HMDB0000019
A10: =AnalysisResults!A10 -> arginine | B10: Amino Acids | C10: HMDB0000517
A11: =AnalysisResults!A11 -> argininic_acid | B11: Organic acids | C11: HMDB0003148
A12: =AnalysisResults!A12 -> asparagine | B12: Amino Acids | C12: HMDB0000168
A13: =AnalysisResults!A13 -> aspartic_acid | B13: Organic acids | C13: HMDB0000191
... A462: =AnalysisResults!A462 -> xanthine | B462: Nucleobases | C462: HMDB0000292

Sheet AnalysisResults
A1: Variable | B1: Mean_WHO | C1: Mean_MD | D1: Diff_in_Means | E1: tStatistic | F1: abs(tStat) | G1: P_value | H1: P_adjusted | I1: HMDB (de BBHI?)
A2: acetoacetic_acid | B2: -0.6207736 | C2: 0.19877894 | D2: -0.81955254 | E2: -1.8831302 | F2: =ABS(E2) -> 1.8831302 | G2: 0.074676098 | H2: 0.85353762
A3: adenosine | B3: -0.00056709686 | C3: 0.10890692 | D3: -0.10947402 | E3: -0.70405118 | F3: =ABS(E3) -> 0.70405118 | G3: 0.48853707 | H3: 0.90870509
A4: alanine | B4: -0.11535125 | C4: 0.059206633 | D4: -0.17455788 | E4: -0.91497146 | F4: =ABS(E4) -> 0.91497146 | G4: 0.37207081 | H4: 0.90870509 | I4: HMDB0000161
A5: allantoin | B5: -0.0033396336 | C5: -0.10024881 | D5: 0.096909177 | E5: 0.66274733 | F5: =ABS(E5) -> 0.66274733 | G5: 0.51358476 | H5: 0.90870509 | I5: HMDB0000462
A6: alpha_aminoadipic_acid | B6: -0.15707524 | C6: 0.071336442 | D6: -0.22841169 | E6: -1.0689571 | F6: =ABS(E6) -> 1.0689571 | G6: 0.29462196 | H6: 0.88875384 | I6: HMDB0000510
A7: alpha_aminobutyric_acid | B7: 0.0507059 | C7: -0.048033602 | D7: 0.098739502 | E7: 0.55639591 | F7: =ABS(E7) -> 0.55639591 | G7: 0.58275698 | H7: 0.92003756 | I7: HMDB0000452
A8: alpha_ketoglutaric_acid | B8: -0.34261349 | C8: -0.066872022 | D8: -0.27574146 | E8: -1.1875967 | F8: =ABS(E8) -> 1.1875967 | G8: 0.24329914 | H8: 0.88875384 | I8: HMDB0000208
A9: alpha_ketoisovaleric_acid | B9: -0.27066091 | C9: -0.025941787 | D9: -0.24471912 | E9: -1.1711368 | F9: =ABS(E9) -> 1.1711368 | G9: 0.2494125 | H9: 0.88875384 | I9: HMDB0000019
A10: arginine | B10: -0.055407544 | C10: -0.1221385 | D10: 0.066730953 | E10: 0.37513944 | F10: =ABS(E10) -> 0.37513944 | G10: 0.71060653 | H10: 0.97415462 | I10: HMDB0000517
A11: argininic_acid | B11: 0.0038549072 | C11: -0.0064498571 | D11: 0.010304764 | E11: 0.20351471 | F11: =ABS(E11) -> 0.20351471 | G11: 0.8400746 | H11: 0.97415462 | I11: HMDB0003148
A12: asparagine | B12: -0.0093429273 | C12: -0.010544195 | D12: 0.0012012678 | E12: 0.0080467908 | F12: =ABS(E12) -> 0.0080467908 | G12: 0.99366494 | H12: 0.99972628 | I12: HMDB0000168
A13: aspartic_acid | B13: -0.15043546 | C13: 0.059458236 | D13: -0.20989369 | E13: -0.83241977 | F13: =ABS(E13) -> 0.83241977 | G13: 0.41493154 | H13: 0.90870509 | I13: HMDB0000191
A14: asymmetric_dimethylarginine | B14: -0.047214691 | C14: -0.012853068 | D14: -0.034361623 | E14: -0.27232302 | F14: =ABS(E14) -> 0.27232302 | G14: 0.78832203 | H14: 0.97415462 | I14: HMDB0001539
A15: asymmetric_dimethylarginine_symmetric_dimethylarginine | B15: -0.054716438 | C15: -0.028229346 | D15: -0.026487092 | E15: -0.1731289 | F15: =ABS(E15) -> 0.1731289 | G15: 0.86436182 | H15: 0.98631386 | I15: HMDB0001539 HMDB0003334
... A21: c4 | B21: 0.09052603 | C21: -0.010750603 | D21: 0.10127663 | E21: 1.1904612 | F21: =ABS(E21) -> 1.1904612 | G21: 0.24722673 | H21: 0.88875384 | I21: HMDB0002013
A22: ce_14_0 | B22: 0.08737979 | C22: -0.043570517 | D22: 0.13095031 | E22: 0.51730488 | F22: =ABS(E22) -> 0.51730488 | G22: 0.60995036 | H22: 0.94358092
A23: ce_14_1 | B23: -0.027404463 | C23: -0.028477091 | D23: 0.0010726272 | E23: 0.0041264162 | F23: =ABS(E23) -> 0.0041264162 | G23: 0.99674108 | H23: 0.99972628
A24: ce_15_0 | B24: 0.080081111 | C24: -0.064853672 | D24: 0.14493478 | E24: 0.58661576 | F24: =ABS(E24) -> 0.58661576 | G24: 0.56364873 | H24: 0.91493685
A25: ce_16_0 | B25: -0.08780234 | C25: -0.039408737 | D25: -0.048393604 | E25: -0.2172883 | F25: =ABS(E25) -> 0.2172883 | G25: 0.83023509 | H25: 0.97415462
A26: ce_16_1 | B26: -0.024656291 | C26: -0.086754792 | D26: 0.062098502 | E26: 0.26111515 | F26: =ABS(E26) -> 0.26111515 | G26: 0.79639889 | H26: 0.97415462 | I26: HMDB0000658
A27: ce_17_0 | B27: 0.0061553081 | C27: -0.090182055 | D27: 0.096337363 | E27: 0.39068677 | F27: =ABS(E27) -> 0.39068677 | G27: 0.69980731 | H27: 0.97415462
A28: ce_17_1 | B28: 0.033527377 | C28: -0.019117172 | D28: 0.052644549 | E28: 0.22287237 | F28: =ABS(E28) -> 0.22287237 | G28: 0.82563014 | H28: 0.97415462
A29: ce_18_0 | B29: -0.095959951 | C29: -0.012396733 | D29: -0.083563218 | E29: -0.36314942 | F29: =ABS(E29) -> 0.36314942 | G29: 0.71995692 | H29: 0.97415462
A30: ce_18_1 | B30: -0.09090911 | C30: -0.011791595 | D30: -0.079117515 | E30: -0.3454119 | F30: =ABS(E30) -> 0.3454119 | G30: 0.7331202 | H30: 0.97415462 | I30: HMDB0000918
A31: ce_18_2 | B31: -0.16620666 | C31: -0.034083043 | D31: -0.13212362 | E31: -0.5733415 | F31: =ABS(E31) -> 0.5733415 | G31: 0.57271767 | H31: 0.91633558 | I31: HMDB0000610
A32: ce_18_3 | B32: 0.014715607 | C32: 0.047558309 | D32: -0.032842702 | E32: -0.12731935 | F32: =ABS(E32) -> 0.12731935 | G32: 0.89976174 | H32: 0.99972628 | I32: HMDB0010369
A33: ce_20_3 | B33: -0.079966259 | C33: -0.077619092 | D33: -0.0023471672 | E33: -0.0095525227 | F33: =ABS(E33) -> 0.0095525227 | G33: 0.9924734 | H33: 0.99972628 | I33: HMDB0006736
A34: ce_20_4 | B34: -0.17007694 | C34: -0.15517792 | D34: -0.014899023 | E34: -0.058816431 | F34: =ABS(E34) -> 0.058816431 | G34: 0.95367724 | H34: 0.99972628 | I34: HMDB0006726
A35: ce_20_5 | B35: -0.14893718 | C35: 0.055889047 | D35: -0.20482623 | E35: -0.85510689 | F35: =ABS(E35) -> 0.85510689 | G35: 0.3992854 | H35: 0.90870509 | I35: HMDB0006731
A36: ce_22_5 | B36: -0.1028857 | C36: -0.1027362 | D36: -0.00014950573 | E36: -0.00064619187 | F36: =ABS(E36) -> 0.00064619187 | G36: 0.9994902 | H36: 0.99972628
A37: ce_22_6 | B37: -0.23210155 | C37: -0.05841997 | D37: -0.17368158 | E37: -0.80043101 | F37: =ABS(E37) -> 0.80043101 | G37: 0.43203419 | H37: 0.90870509 | I37: HMDB0006733
A38: cer_d16_1_22_0 | B38: -0.023267284 | C38: -0.030621894 | D38: 0.00735461 | E38: 0.13499238 | F38: =ABS(E38) -> 0.13499238 | G38: 0.89356227 | H38: 0.99972628
A39: cer_d16_1_24_0 | B39: -0.049107095 | C39: -0.068409084 | D39: 0.019301988 | E39: 0.30736885 | F39: =ABS(E39) -> 0.30736885 | G39: 0.76088391 | H39: 0.97415462
A40: cer_d18_1_16_0 | B40: -0.096444842 | C40: 0.007081212 | D40: -0.10352605 | E40: -0.83250993 | F40: =ABS(E40) -> 0.83250993 | G40: 0.41575115 | H40: 0.90870509 | I40: HMDB0000790
A41: cer_d18_1_18_0 | B41: -0.091937751 | C41: -0.021568789 | D41: -0.070368962 | E41: -0.75743746 | F41: =ABS(E41) -> 0.75743746 | G41: 0.45787511 | H41: 0.90870509
A42: cer_d18_1_22_0 | B42: -0.08100486 | C42: -0.053196243 | D42: -0.027808617 | E42: -0.25462925 | F42: =ABS(E42) -> 0.25462925 | G42: 0.8014264 | H42: 0.97415462 | I42: HMDB0004952
A43: cer_d18_1_23_0 | B43: -0.10644388 | C43: -0.022020571 | D43: -0.084423306 | E43: -0.77884258 | F43: =ABS(E43) -> 0.77884258 | G43: 0.44360483 | H43: 0.90870509 | I43: HMDB0000950
A44: cer_d18_1_24_0 | B44: -0.16748249 | C44: -0.082902032 | D44: -0.08458046 | E44: -0.61006695 | F44: =ABS(E44) -> 0.61006695 | G44: 0.54867492 | H44: 0.90870509 | I44: HMDB0004956
A45: cer_d18_1_24_1 | B45: -0.10031381 | C45: -0.00095788643 | D45: -0.099355928 | E45: -0.71988847 | F45: =ABS(E45) -> 0.71988847 | G45: 0.47921884 | H45: 0.90870509 | I45: HMDB0004953
...
